<?xml version="1.0" ?>
<!-- =================================================================================== -->
<!-- |    This document was autogenerated by xacro from crab_model.xacro               | -->
<!-- |    EDITING THIS FILE BY HAND IS NOT RECOMMENDED                                 | -->
<!-- =================================================================================== -->
<robot name="crab" xmlns:xacro="http://ros.org/wiki/xacro">
  <!-- Build the body frame -->
  <link name="world"/>
  <joint name="base_joint" type="fixed">
    <parent link="world"/>
    <child link="thorax"/>
    <origin rpy="0 0 0" xyz="0 0 0"/>
  </joint>
  <link name="thorax">
    <visual>
      <origin rpy="0 0 0" xyz="0 0 0"/>
      <geometry>
        <mesh filename="package://crab_description/meshes/thorax.STL"/>
      </geometry>
      <material name="grey">
        <color rgba="0.5 0.5 0.5 1"/>
      </material>
    </visual>
    <inertial>
      <origin rpy="0 0 0" xyz="0 0 0"/>
      <mass value="1"/>
      <inertia ixx="0" ixy="0.0" ixz="0.0" iyy="0" iyz="0.0" izz="0"/>
    </inertial>
  </link>
  <gazebo reference="thorax">
    <material>Gazebo/White</material>
    <selfCollide>true</selfCollide>
  </gazebo>
  <!-- Pi parameter -->
  <!-- Joint properties -->
  <!-- Leg macros -->
  <!-- Build robot model -->
  <!-- Build leg -->
  <joint name="leg_center_joint_r1" type="fixed">
    <origin rpy="0 0 0" xyz="0.087598 -0.050575 0"/>
    <parent link="thorax"/>
    <child link="leg_center_r1"/>
  </joint>
  <link name="leg_center_r1">
    <inertial>
      <origin rpy="0 0 0" xyz="0 0 0"/>
      <mass value="1"/>
      <inertia ixx="0" ixy="0.0" ixz="0.0" iyy="0" iyz="0.0" izz="0"/>
    </inertial>
  </link>
  <gazebo reference="leg_center_r1">
    <material>Gazebo/White</material>
    <selfCollide>true</selfCollide>
  </gazebo>
  <joint name="coxa_joint_r1" type="revolute">
    <origin rpy="0 0 -1.0471975512" xyz="0 0 0"/>
    <parent link="leg_center_r1"/>
    <child link="coxa_r1"/>
    <axis xyz="0 0 -1"/>
    <limit effort="10000" lower="-1.5" upper="1.5" velocity="100"/>
  </joint>
  <link name="coxa_r1">
    <visual>
      <origin rpy="0 0 0" xyz="0 0 0"/>
      <geometry>
        <mesh filename="package://crab_description/meshes/coxa_r.STL"/>
      </geometry>
      <material name="">
        <color rgba="0.7 0.7 0 1"/>
      </material>
    </visual>
    <inertial>
      <origin rpy="0 0 0" xyz="0 0 0"/>
      <mass value="1"/>
      <inertia ixx="0" ixy="0.0" ixz="0.0" iyy="0" iyz="0.0" izz="0"/>
    </inertial>
  </link>
  <gazebo reference="coxa_r1">
    <material>Gazebo/White</material>
    <selfCollide>true</selfCollide>
  </gazebo>
  <joint name="femur_joint_r1" type="revolute">
    <origin rpy="-1.57079632679 0 0" xyz="0.0294 0 0"/>
    <parent link="coxa_r1"/>
    <child link="femur_r1"/>
    <axis xyz="0 0 -1"/>
    <limit effort="10000" lower="-1.5" upper="1.5" velocity="100"/>
  </joint>
  <link name="femur_r1">
    <visual>
      <origin rpy="0 0 0" xyz="0 0 0"/>
      <geometry>
        <mesh filename="package://crab_description/meshes/femur_r.STL"/>
      </geometry>
      <material name="">
        <color rgba="0 0.7 0.7 1"/>
      </material>
    </visual>
    <inertial>
      <origin rpy="0 0 0" xyz="0 0 0"/>
      <mass value="1"/>
      <inertia ixx="0" ixy="0.0" ixz="0.0" iyy="0" iyz="0.0" izz="0"/>
    </inertial>
  </link>
  <gazebo reference="femur_r1">
    <material>Gazebo/White</material>
    <selfCollide>true</selfCollide>
  </gazebo>
  <joint name="tibia_joint_r1" type="revolute">
    <origin rpy="3.14159265359 0 1.57079632679" xyz="0.08 0 0"/>
    <parent link="femur_r1"/>
    <child link="tibia_r1"/>
    <axis xyz="0 0 1"/>
    <limit effort="10000" lower="-1.5" upper="1.5" velocity="100"/>
  </joint>
  <link name="tibia_r1">
    <visual>
      <origin rpy="0 0 0" xyz="0 0 0"/>
      <geometry>
        <mesh filename="package://crab_description/meshes/tibia_r.STL"/>
      </geometry>
      <material name="">
        <color rgba="0.7 0 0.7 1"/>
      </material>
    </visual>
    <inertial>
      <origin rpy="0 0 0" xyz="0 0 0"/>
      <mass value="1"/>
      <inertia ixx="0" ixy="0.0" ixz="0.0" iyy="0" iyz="0.0" izz="0"/>
    </inertial>
  </link>
  <gazebo reference="tibia_r1">
    <material>Gazebo/White</material>
    <selfCollide>true</selfCollide>
  </gazebo>
  <joint name="tibia_foot_joint_r1" type="fixed">
    <origin rpy="0 0 0" xyz="0.117 0 0"/>
    <parent link="tibia_r1"/>
    <child link="tibia_foot_r1"/>
  </joint>
  <link name="tibia_foot_r1">
    <inertial>
      <origin rpy="0 0 0" xyz="0 0 0"/>
      <mass value="1"/>
      <inertia ixx="0" ixy="0.0" ixz="0.0" iyy="0" iyz="0.0" izz="0"/>
    </inertial>
  </link>
  <gazebo reference="tibia_foot_r1">
    <material>Gazebo/White</material>
    <selfCollide>true</selfCollide>
  </gazebo>
  <!-- Build leg -->
  <joint name="leg_center_joint_r2" type="fixed">
    <origin rpy="0 0 0" xyz="0 -0.06985 0"/>
    <parent link="thorax"/>
    <child link="leg_center_r2"/>
  </joint>
  <link name="leg_center_r2">
    <inertial>
      <origin rpy="0 0 0" xyz="0 0 0"/>
      <mass value="1"/>
      <inertia ixx="0" ixy="0.0" ixz="0.0" iyy="0" iyz="0.0" izz="0"/>
    </inertial>
  </link>
  <gazebo reference="leg_center_r2">
    <material>Gazebo/White</material>
    <selfCollide>true</selfCollide>
  </gazebo>
  <joint name="coxa_joint_r2" type="revolute">
    <origin rpy="0 0 -1.57079632679" xyz="0 0 0"/>
    <parent link="leg_center_r2"/>
    <child link="coxa_r2"/>
    <axis xyz="0 0 -1"/>
    <limit effort="10000" lower="-1.5" upper="1.5" velocity="100"/>
  </joint>
  <link name="coxa_r2">
    <visual>
      <origin rpy="0 0 0" xyz="0 0 0"/>
      <geometry>
        <mesh filename="package://crab_description/meshes/coxa_r.STL"/>
      </geometry>
      <material name="">
        <color rgba="0.7 0.7 0 1"/>
      </material>
    </visual>
    <inertial>
      <origin rpy="0 0 0" xyz="0 0 0"/>
      <mass value="1"/>
      <inertia ixx="0" ixy="0.0" ixz="0.0" iyy="0" iyz="0.0" izz="0"/>
    </inertial>
  </link>
  <gazebo reference="coxa_r2">
    <material>Gazebo/White</material>
    <selfCollide>true</selfCollide>
  </gazebo>
  <joint name="femur_joint_r2" type="revolute">
    <origin rpy="-1.57079632679 0 0" xyz="0.0294 0 0"/>
    <parent link="coxa_r2"/>
    <child link="femur_r2"/>
    <axis xyz="0 0 -1"/>
    <limit effort="10000" lower="-1.5" upper="1.5" velocity="100"/>
  </joint>
  <link name="femur_r2">
    <visual>
      <origin rpy="0 0 0" xyz="0 0 0"/>
      <geometry>
        <mesh filename="package://crab_description/meshes/femur_r.STL"/>
      </geometry>
      <material name="">
        <color rgba="0 0.7 0.7 1"/>
      </material>
    </visual>
    <inertial>
      <origin rpy="0 0 0" xyz="0 0 0"/>
      <mass value="1"/>
      <inertia ixx="0" ixy="0.0" ixz="0.0" iyy="0" iyz="0.0" izz="0"/>
    </inertial>
  </link>
  <gazebo reference="femur_r2">
    <material>Gazebo/White</material>
    <selfCollide>true</selfCollide>
  </gazebo>
  <joint name="tibia_joint_r2" type="revolute">
    <origin rpy="3.14159265359 0 1.57079632679" xyz="0.08 0 0"/>
    <parent link="femur_r2"/>
    <child link="tibia_r2"/>
    <axis xyz="0 0 1"/>
    <limit effort="10000" lower="-1.5" upper="1.5" velocity="100"/>
  </joint>
  <link name="tibia_r2">
    <visual>
      <origin rpy="0 0 0" xyz="0 0 0"/>
      <geometry>
        <mesh filename="package://crab_description/meshes/tibia_r.STL"/>
      </geometry>
      <material name="">
        <color rgba="0.7 0 0.7 1"/>
      </material>
    </visual>
    <inertial>
      <origin rpy="0 0 0" xyz="0 0 0"/>
      <mass value="1"/>
      <inertia ixx="0" ixy="0.0" ixz="0.0" iyy="0" iyz="0.0" izz="0"/>
    </inertial>
  </link>
  <gazebo reference="tibia_r2">
    <material>Gazebo/White</material>
    <selfCollide>true</selfCollide>
  </gazebo>
  <joint name="tibia_foot_joint_r2" type="fixed">
    <origin rpy="0 0 0" xyz="0.117 0 0"/>
    <parent link="tibia_r2"/>
    <child link="tibia_foot_r2"/>
  </joint>
  <link name="tibia_foot_r2">
    <inertial>
      <origin rpy="0 0 0" xyz="0 0 0"/>
      <mass value="1"/>
      <inertia ixx="0" ixy="0.0" ixz="0.0" iyy="0" iyz="0.0" izz="0"/>
    </inertial>
  </link>
  <gazebo reference="tibia_foot_r2">
    <material>Gazebo/White</material>
    <selfCollide>true</selfCollide>
  </gazebo>
  <!-- Build leg -->
  <joint name="leg_center_joint_r3" type="fixed">
    <origin rpy="0 0 0" xyz="-0.087598 -0.050575 0"/>
    <parent link="thorax"/>
    <child link="leg_center_r3"/>
  </joint>
  <link name="leg_center_r3">
    <inertial>
      <origin rpy="0 0 0" xyz="0 0 0"/>
      <mass value="1"/>
      <inertia ixx="0" ixy="0.0" ixz="0.0" iyy="0" iyz="0.0" izz="0"/>
    </inertial>
  </link>
  <gazebo reference="leg_center_r3">
    <material>Gazebo/White</material>
    <selfCollide>true</selfCollide>
  </gazebo>
  <joint name="coxa_joint_r3" type="revolute">
    <origin rpy="0 0 -2.09439510239" xyz="0 0 0"/>
    <parent link="leg_center_r3"/>
    <child link="coxa_r3"/>
    <axis xyz="0 0 -1"/>
    <limit effort="10000" lower="-1.5" upper="1.5" velocity="100"/>
  </joint>
  <link name="coxa_r3">
    <visual>
      <origin rpy="0 0 0" xyz="0 0 0"/>
      <geometry>
        <mesh filename="package://crab_description/meshes/coxa_r.STL"/>
      </geometry>
      <material name="">
        <color rgba="0.7 0.7 0 1"/>
      </material>
    </visual>
    <inertial>
      <origin rpy="0 0 0" xyz="0 0 0"/>
      <mass value="1"/>
      <inertia ixx="0" ixy="0.0" ixz="0.0" iyy="0" iyz="0.0" izz="0"/>
    </inertial>
  </link>
  <gazebo reference="coxa_r3">
    <material>Gazebo/White</material>
    <selfCollide>true</selfCollide>
  </gazebo>
  <joint name="femur_joint_r3" type="revolute">
    <origin rpy="-1.57079632679 0 0" xyz="0.0294 0 0"/>
    <parent link="coxa_r3"/>
    <child link="femur_r3"/>
    <axis xyz="0 0 -1"/>
    <limit effort="10000" lower="-1.5" upper="1.5" velocity="100"/>
  </joint>
  <link name="femur_r3">
    <visual>
      <origin rpy="0 0 0" xyz="0 0 0"/>
      <geometry>
        <mesh filename="package://crab_description/meshes/femur_r.STL"/>
      </geometry>
      <material name="">
        <color rgba="0 0.7 0.7 1"/>
      </material>
    </visual>
    <inertial>
      <origin rpy="0 0 0" xyz="0 0 0"/>
      <mass value="1"/>
      <inertia ixx="0" ixy="0.0" ixz="0.0" iyy="0" iyz="0.0" izz="0"/>
    </inertial>
  </link>
  <gazebo reference="femur_r3">
    <material>Gazebo/White</material>
    <selfCollide>true</selfCollide>
  </gazebo>
  <joint name="tibia_joint_r3" type="revolute">
    <origin rpy="3.14159265359 0 1.57079632679" xyz="0.08 0 0"/>
    <parent link="femur_r3"/>
    <child link="tibia_r3"/>
    <axis xyz="0 0 1"/>
    <limit effort="10000" lower="-1.5" upper="1.5" velocity="100"/>
  </joint>
  <link name="tibia_r3">
    <visual>
      <origin rpy="0 0 0" xyz="0 0 0"/>
      <geometry>
        <mesh filename="package://crab_description/meshes/tibia_r.STL"/>
      </geometry>
      <material name="">
        <color rgba="0.7 0 0.7 1"/>
      </material>
    </visual>
    <inertial>
      <origin rpy="0 0 0" xyz="0 0 0"/>
      <mass value="1"/>
      <inertia ixx="0" ixy="0.0" ixz="0.0" iyy="0" iyz="0.0" izz="0"/>
    </inertial>
  </link>
  <gazebo reference="tibia_r3">
    <material>Gazebo/White</material>
    <selfCollide>true</selfCollide>
  </gazebo>
  <joint name="tibia_foot_joint_r3" type="fixed">
    <origin rpy="0 0 0" xyz="0.117 0 0"/>
    <parent link="tibia_r3"/>
    <child link="tibia_foot_r3"/>
  </joint>
  <link name="tibia_foot_r3">
    <inertial>
      <origin rpy="0 0 0" xyz="0 0 0"/>
      <mass value="1"/>
      <inertia ixx="0" ixy="0.0" ixz="0.0" iyy="0" iyz="0.0" izz="0"/>
    </inertial>
  </link>
  <gazebo reference="tibia_foot_r3">
    <material>Gazebo/White</material>
    <selfCollide>true</selfCollide>
  </gazebo>
  <!-- Build leg -->
  <joint name="leg_center_joint_l1" type="fixed">
    <origin rpy="0 0 0" xyz="0.087598 0.050575 0"/>
    <parent link="thorax"/>
    <child link="leg_center_l1"/>
  </joint>
  <link name="leg_center_l1">
    <inertial>
      <origin rpy="0 0 0" xyz="0 0 0"/>
      <mass value="1"/>
      <inertia ixx="0" ixy="0.0" ixz="0.0" iyy="0" iyz="0.0" izz="0"/>
    </inertial>
  </link>
  <gazebo reference="leg_center_l1">
    <material>Gazebo/White</material>
    <selfCollide>true</selfCollide>
  </gazebo>
  <joint name="coxa_joint_l1" type="revolute">
    <origin rpy="0 0 1.0471975512" xyz="0 0 0"/>
    <parent link="leg_center_l1"/>
    <child link="coxa_l1"/>
    <axis xyz="0 0 -1"/>
    <limit effort="10000" lower="-1.5" upper="1.5" velocity="100"/>
  </joint>
  <link name="coxa_l1">
    <visual>
      <origin rpy="0 0 0" xyz="0 0 0"/>
      <geometry>
        <mesh filename="package://crab_description/meshes/coxa_l.STL"/>
      </geometry>
      <material name="">
        <color rgba="0.7 0.7 0 1"/>
      </material>
    </visual>
    <inertial>
      <origin rpy="0 0 0" xyz="0 0 0"/>
      <mass value="1"/>
      <inertia ixx="0" ixy="0.0" ixz="0.0" iyy="0" iyz="0.0" izz="0"/>
    </inertial>
  </link>
  <gazebo reference="coxa_l1">
    <material>Gazebo/White</material>
    <selfCollide>true</selfCollide>
  </gazebo>
  <joint name="femur_joint_l1" type="revolute">
    <origin rpy="-1.57079632679 0 0" xyz="0.0294 0 0"/>
    <parent link="coxa_l1"/>
    <child link="femur_l1"/>
    <axis xyz="0 0 -1"/>
    <limit effort="10000" lower="-1.5" upper="1.5" velocity="100"/>
  </joint>
  <link name="femur_l1">
    <visual>
      <origin rpy="0 0 0" xyz="0 0 0"/>
      <geometry>
        <mesh filename="package://crab_description/meshes/femur_l.STL"/>
      </geometry>
      <material name="">
        <color rgba="0 0.7 0.7 1"/>
      </material>
    </visual>
    <inertial>
      <origin rpy="0 0 0" xyz="0 0 0"/>
      <mass value="1"/>
      <inertia ixx="0" ixy="0.0" ixz="0.0" iyy="0" iyz="0.0" izz="0"/>
    </inertial>
  </link>
  <gazebo reference="femur_l1">
    <material>Gazebo/White</material>
    <selfCollide>true</selfCollide>
  </gazebo>
  <joint name="tibia_joint_l1" type="revolute">
    <origin rpy="3.14159265359 0 1.57079632679" xyz="0.08 0 0"/>
    <parent link="femur_l1"/>
    <child link="tibia_l1"/>
    <axis xyz="0 0 1"/>
    <limit effort="10000" lower="-1.5" upper="1.5" velocity="100"/>
  </joint>
  <link name="tibia_l1">
    <visual>
      <origin rpy="0 0 0" xyz="0 0 0"/>
      <geometry>
        <mesh filename="package://crab_description/meshes/tibia_l.STL"/>
      </geometry>
      <material name="">
        <color rgba="0.7 0 0.7 1"/>
      </material>
    </visual>
    <inertial>
      <origin rpy="0 0 0" xyz="0 0 0"/>
      <mass value="1"/>
      <inertia ixx="0" ixy="0.0" ixz="0.0" iyy="0" iyz="0.0" izz="0"/>
    </inertial>
  </link>
  <gazebo reference="tibia_l1">
    <material>Gazebo/White</material>
    <selfCollide>true</selfCollide>
  </gazebo>
  <joint name="tibia_foot_joint_l1" type="fixed">
    <origin rpy="0 0 0" xyz="0.117 0 0"/>
    <parent link="tibia_l1"/>
    <child link="tibia_foot_l1"/>
  </joint>
  <link name="tibia_foot_l1">
    <inertial>
      <origin rpy="0 0 0" xyz="0 0 0"/>
      <mass value="1"/>
      <inertia ixx="0" ixy="0.0" ixz="0.0" iyy="0" iyz="0.0" izz="0"/>
    </inertial>
  </link>
  <gazebo reference="tibia_foot_l1">
    <material>Gazebo/White</material>
    <selfCollide>true</selfCollide>
  </gazebo>
  <!-- Build leg -->
  <joint name="leg_center_joint_l2" type="fixed">
    <origin rpy="0 0 0" xyz="0 0.06985 0"/>
    <parent link="thorax"/>
    <child link="leg_center_l2"/>
  </joint>
  <link name="leg_center_l2">
    <inertial>
      <origin rpy="0 0 0" xyz="0 0 0"/>
      <mass value="1"/>
      <inertia ixx="0" ixy="0.0" ixz="0.0" iyy="0" iyz="0.0" izz="0"/>
    </inertial>
  </link>
  <gazebo reference="leg_center_l2">
    <material>Gazebo/White</material>
    <selfCollide>true</selfCollide>
  </gazebo>
  <joint name="coxa_joint_l2" type="revolute">
    <origin rpy="0 0 1.57079632679" xyz="0 0 0"/>
    <parent link="leg_center_l2"/>
    <child link="coxa_l2"/>
    <axis xyz="0 0 -1"/>
    <limit effort="10000" lower="-1.5" upper="1.5" velocity="100"/>
  </joint>
  <link name="coxa_l2">
    <visual>
      <origin rpy="0 0 0" xyz="0 0 0"/>
      <geometry>
        <mesh filename="package://crab_description/meshes/coxa_l.STL"/>
      </geometry>
      <material name="">
        <color rgba="0.7 0.7 0 1"/>
      </material>
    </visual>
    <inertial>
      <origin rpy="0 0 0" xyz="0 0 0"/>
      <mass value="1"/>
      <inertia ixx="0" ixy="0.0" ixz="0.0" iyy="0" iyz="0.0" izz="0"/>
    </inertial>
  </link>
  <gazebo reference="coxa_l2">
    <material>Gazebo/White</material>
    <selfCollide>true</selfCollide>
  </gazebo>
  <joint name="femur_joint_l2" type="revolute">
    <origin rpy="-1.57079632679 0 0" xyz="0.0294 0 0"/>
    <parent link="coxa_l2"/>
    <child link="femur_l2"/>
    <axis xyz="0 0 -1"/>
    <limit effort="10000" lower="-1.5" upper="1.5" velocity="100"/>
  </joint>
  <link name="femur_l2">
    <visual>
      <origin rpy="0 0 0" xyz="0 0 0"/>
      <geometry>
        <mesh filename="package://crab_description/meshes/femur_l.STL"/>
      </geometry>
      <material name="">
        <color rgba="0 0.7 0.7 1"/>
      </material>
    </visual>
    <inertial>
      <origin rpy="0 0 0" xyz="0 0 0"/>
      <mass value="1"/>
      <inertia ixx="0" ixy="0.0" ixz="0.0" iyy="0" iyz="0.0" izz="0"/>
    </inertial>
  </link>
  <gazebo reference="femur_l2">
    <material>Gazebo/White</material>
    <selfCollide>true</selfCollide>
  </gazebo>
  <joint name="tibia_joint_l2" type="revolute">
    <origin rpy="3.14159265359 0 1.57079632679" xyz="0.08 0 0"/>
    <parent link="femur_l2"/>
    <child link="tibia_l2"/>
    <axis xyz="0 0 1"/>
    <limit effort="10000" lower="-1.5" upper="1.5" velocity="100"/>
  </joint>
  <link name="tibia_l2">
    <visual>
      <origin rpy="0 0 0" xyz="0 0 0"/>
      <geometry>
        <mesh filename="package://crab_description/meshes/tibia_l.STL"/>
      </geometry>
      <material name="">
        <color rgba="0.7 0 0.7 1"/>
      </material>
    </visual>
    <inertial>
      <origin rpy="0 0 0" xyz="0 0 0"/>
      <mass value="1"/>
      <inertia ixx="0" ixy="0.0" ixz="0.0" iyy="0" iyz="0.0" izz="0"/>
    </inertial>
  </link>
  <gazebo reference="tibia_l2">
    <material>Gazebo/White</material>
    <selfCollide>true</selfCollide>
  </gazebo>
  <joint name="tibia_foot_joint_l2" type="fixed">
    <origin rpy="0 0 0" xyz="0.117 0 0"/>
    <parent link="tibia_l2"/>
    <child link="tibia_foot_l2"/>
  </joint>
  <link name="tibia_foot_l2">
    <inertial>
      <origin rpy="0 0 0" xyz="0 0 0"/>
      <mass value="1"/>
      <inertia ixx="0" ixy="0.0" ixz="0.0" iyy="0" iyz="0.0" izz="0"/>
    </inertial>
  </link>
  <gazebo reference="tibia_foot_l2">
    <material>Gazebo/White</material>
    <selfCollide>true</selfCollide>
  </gazebo>
  <!-- Build leg -->
  <joint name="leg_center_joint_l3" type="fixed">
    <origin rpy="0 0 0" xyz="-0.087598 0.050575 0"/>
    <parent link="thorax"/>
    <child link="leg_center_l3"/>
  </joint>
  <link name="leg_center_l3">
    <inertial>
      <origin rpy="0 0 0" xyz="0 0 0"/>
      <mass value="1"/>
      <inertia ixx="0" ixy="0.0" ixz="0.0" iyy="0" iyz="0.0" izz="0"/>
    </inertial>
  </link>
  <gazebo reference="leg_center_l3">
    <material>Gazebo/White</material>
    <selfCollide>true</selfCollide>
  </gazebo>
  <joint name="coxa_joint_l3" type="revolute">
    <origin rpy="0 0 2.09439510239" xyz="0 0 0"/>
    <parent link="leg_center_l3"/>
    <child link="coxa_l3"/>
    <axis xyz="0 0 -1"/>
    <limit effort="10000" lower="-1.5" upper="1.5" velocity="100"/>
  </joint>
  <link name="coxa_l3">
    <visual>
      <origin rpy="0 0 0" xyz="0 0 0"/>
      <geometry>
        <mesh filename="package://crab_description/meshes/coxa_l.STL"/>
      </geometry>
      <material name="">
        <color rgba="0.7 0.7 0 1"/>
      </material>
    </visual>
    <inertial>
      <origin rpy="0 0 0" xyz="0 0 0"/>
      <mass value="1"/>
      <inertia ixx="0" ixy="0.0" ixz="0.0" iyy="0" iyz="0.0" izz="0"/>
    </inertial>
  </link>
  <gazebo reference="coxa_l3">
    <material>Gazebo/White</material>
    <selfCollide>true</selfCollide>
  </gazebo>
  <joint name="femur_joint_l3" type="revolute">
    <origin rpy="-1.57079632679 0 0" xyz="0.0294 0 0"/>
    <parent link="coxa_l3"/>
    <child link="femur_l3"/>
    <axis xyz="0 0 -1"/>
    <limit effort="10000" lower="-1.5" upper="1.5" velocity="100"/>
  </joint>
  <link name="femur_l3">
    <visual>
      <origin rpy="0 0 0" xyz="0 0 0"/>
      <geometry>
        <mesh filename="package://crab_description/meshes/femur_l.STL"/>
      </geometry>
      <material name="">
        <color rgba="0 0.7 0.7 1"/>
      </material>
    </visual>
    <inertial>
      <origin rpy="0 0 0" xyz="0 0 0"/>
      <mass value="1"/>
      <inertia ixx="0" ixy="0.0" ixz="0.0" iyy="0" iyz="0.0" izz="0"/>
    </inertial>
  </link>
  <gazebo reference="femur_l3">
    <material>Gazebo/White</material>
    <selfCollide>true</selfCollide>
  </gazebo>
  <joint name="tibia_joint_l3" type="revolute">
    <origin rpy="3.14159265359 0 1.57079632679" xyz="0.08 0 0"/>
    <parent link="femur_l3"/>
    <child link="tibia_l3"/>
    <axis xyz="0 0 1"/>
    <limit effort="10000" lower="-1.5" upper="1.5" velocity="100"/>
  </joint>
  <link name="tibia_l3">
    <visual>
      <origin rpy="0 0 0" xyz="0 0 0"/>
      <geometry>
        <mesh filename="package://crab_description/meshes/tibia_l.STL"/>
      </geometry>
      <material name="">
        <color rgba="0.7 0 0.7 1"/>
      </material>
    </visual>
    <inertial>
      <origin rpy="0 0 0" xyz="0 0 0"/>
      <mass value="1"/>
      <inertia ixx="0" ixy="0.0" ixz="0.0" iyy="0" iyz="0.0" izz="0"/>
    </inertial>
  </link>
  <gazebo reference="tibia_l3">
    <material>Gazebo/White</material>
    <selfCollide>true</selfCollide>
  </gazebo>
  <joint name="tibia_foot_joint_l3" type="fixed">
    <origin rpy="0 0 0" xyz="0.117 0 0"/>
    <parent link="tibia_l3"/>
    <child link="tibia_foot_l3"/>
  </joint>
  <link name="tibia_foot_l3">
    <inertial>
      <origin rpy="0 0 0" xyz="0 0 0"/>
      <mass value="1"/>
      <inertia ixx="0" ixy="0.0" ixz="0.0" iyy="0" iyz="0.0" izz="0"/>
    </inertial>
  </link>
  <gazebo reference="tibia_foot_l3">
    <material>Gazebo/White</material>
    <selfCollide>true</selfCollide>
  </gazebo>
</robot>
